2025-05-13 23:39:34,803: Exception on /room_stats [GET]
Traceback (most recent call last):
  File "/home/Tayo9M/venv/lib/python3.9/site-packages/flask/app.py", line 2073, in wsgi_app
    response = self.full_dispatch_request()
  File "/home/Tayo9M/venv/lib/python3.9/site-packages/flask/app.py", line 1518, in full_dispatch_request
    rv = self.handle_user_exception(e)
  File "/home/Tayo9M/venv/lib/python3.9/site-packages/flask/app.py", line 1516, in full_dispatch_request
    rv = self.dispatch_request()
  File "/home/Tayo9M/venv/lib/python3.9/site-packages/flask/app.py", line 1502, in dispatch_request
    return self.ensure_sync(self.view_functions[rule.endpoint])(**req.view_args)
  File "/home/Tayo9M/venv/lib/python3.9/site-packages/flask_login/utils.py", line 272, in decorated_view
    return func(*args, **kwargs)
  File "/home/Tayo9M/sistem-pencatatan-penginapan-kos/./routes.py", line 689, in room_stats
    plt.figure(figsize=(10, 6))
NameError: name 'plt' is not defined
2025-05-13 23:51:18,803: Exception on /room_stats [GET]
Traceback (most recent call last):
  File "/home/Tayo9M/venv/lib/python3.9/site-packages/flask/app.py", line 2073, in wsgi_app
    response = self.full_dispatch_request()
  File "/home/Tayo9M/venv/lib/python3.9/site-packages/flask/app.py", line 1518, in full_dispatch_request
    rv = self.handle_user_exception(e)
  File "/home/Tayo9M/venv/lib/python3.9/site-packages/flask/app.py", line 1516, in full_dispatch_request
    rv = self.dispatch_request()
  File "/home/Tayo9M/venv/lib/python3.9/site-packages/flask/app.py", line 1502, in dispatch_request
    return self.ensure_sync(self.view_functions[rule.endpoint])(**req.view_args)
  File "/home/Tayo9M/venv/lib/python3.9/site-packages/flask_login/utils.py", line 272, in decorated_view
    return func(*args, **kwargs)
  File "/home/Tayo9M/sistem-pencatatan-penginapan-kos/./routes.py", line 661, in room_stats
    room_types_list = [rt[0] for rt in room_types]
NameError: name 'room_types' is not defined
2025-05-13 23:51:26,963: Exception on /financial_stats [GET]
Traceback (most recent call last):
  File "/home/Tayo9M/venv/lib/python3.9/site-packages/flask/app.py", line 2073, in wsgi_app
    response = self.full_dispatch_request()
  File "/home/Tayo9M/venv/lib/python3.9/site-packages/flask/app.py", line 1518, in full_dispatch_request
    rv = self.handle_user_exception(e)
  File "/home/Tayo9M/venv/lib/python3.9/site-packages/flask/app.py", line 1516, in full_dispatch_request
    rv = self.dispatch_request()
  File "/home/Tayo9M/venv/lib/python3.9/site-packages/flask/app.py", line 1502, in dispatch_request
    return self.ensure_sync(self.view_functions[rule.endpoint])(**req.view_args)
  File "/home/Tayo9M/venv/lib/python3.9/site-packages/flask_login/utils.py", line 272, in decorated_view
    return func(*args, **kwargs)
  File "/home/Tayo9M/sistem-pencatatan-penginapan-kos/./routes.py", line 779, in financial_stats
    x = range(len(months))
NameError: name 'months' is not defined